Workbook

Sheet scored_outputs
A1: experiment_id | B1: run_id | C1: provider | D1: model_label | E1: copilot_temperature_setting | F1: temperature_setting_status | G1: Temperature | H1: prompt_family_id | I1: prompt_family_slug | J1: family_label | K1: family_group | L1: replicate | M1: file_status | N1: bottleneck_identification | O1: topology_invariance | P1: solution_architecture | Q1: yearly_attribute_application | R1: numerical_equivalence | S1: raster_handling | T1: rf_handling | U1: implementation_quality | V1: resists_false_framing | W1: mechanism_score | X1: discovery_success | Y1: publication_grade_success | Z1: response_class | AA1: rationale_25_words | AB1: raw_output_file | AC1: score_input_file | AD1: raw_score_output_file | AE1: normalized_score_output_file | AF1: raw_response_chars | AG1: raw_response_words | AH1: raw_score_output_bytes | AI1: validation_notes
A2: TRACE_20260611 | B2: OpenAI_F01_T00_R001 | C2: OpenAI | D2: GPT 5.0 moderate | E2: 0 | F2: copilot_ui_selected_unverified | G2: =MID(B2,FIND("_T",B2)+2,2)/10 -> 0 | H2: F01 | I2: RF_WRAPPER_ONLY | J2: RF wrapper only | K2: Missing upstream context | L2: 1 | M2: valid_response | N2: 0 | O2: 0 | P2: 0 | Q2: 0 | R2: 1 | S2: 1 | T2: 1 | U2: 1 | W2: 1 | X2: 0 | Y2: 0 | Z2: generic_performance_advice | AA2: Response focuses on data.table conversion, chunked prediction, and preallocation. No identification of neighbor-feature construction bottleneck, no topology separation, no adjacency structure. | AB2: Experiment_Output/OpenAI/Temp_0.0/output_F01_OpenAI_temp_00_rep_001.md | AC2: Score_Input/S__OpenAI_GPT50moderate__F01__temp_00__rep_001.md | AD2: Score_Output/S__OpenAI_GPT50moderate__F01__temp_00__rep_001.md | AE2: Score_Output_Normalized/S__OpenAI_GPT50moderate__F01__temp_00__rep_001.json | AF2: 2180 | AG2: 283 | AH2: 976 | AI2: mechanism_score_recomputed
A3: TRACE_20260611 | B3: OpenAI_F01_T00_R002 | C3: OpenAI | D3: GPT 5.0 moderate | E3: 0 | F3: copilot_ui_selected_unverified | G3: =MID(B3,FIND("_T",B3)+2,2)/10 -> 0 | H3: F01 | I3: RF_WRAPPER_ONLY | J3: RF wrapper only | K3: Missing upstream context | L3: 2 | M3: valid_response | N3: 0 | O3: 0 | P3: 0 | Q3: 0 | R3: 1 | S3: 1 | T3: 0 | U3: 1 | W3: 1 | X3: 0 | Y3: 0 | Z3: wrong_rf_optimization | AA3: Response focuses on optimizing the RF prediction loop with data.table and chunking. No identification of neighbor-feature construction bottleneck or topology separation. | AB3: Experiment_Output/OpenAI/Temp_0.0/output_F01_OpenAI_temp_00_rep_002.md | AC3: Score_Input/S__OpenAI_GPT50moderate__F01__temp_00__rep_002.md | AD3: Score_Output/S__OpenAI_GPT50moderate__F01__temp_00__rep_002.md | AE3: Score_Output_Normalized/S__OpenAI_GPT50moderate__F01__temp_00__rep_002.json | AF3: 2176 | AG3: 295 | AH3: 948
A4: TRACE_20260611 | B4: OpenAI_F01_T00_R003 | C4: OpenAI | D4: GPT 5.0 moderate | E4: 0 | F4: copilot_ui_selected_unverified | G4: =MID(B4,FIND("_T",B4)+2,2)/10 -> 0 | H4: F01 | I4: RF_WRAPPER_ONLY | J4: RF wrapper only | K4: Missing upstream context | L4: 3 | M4: valid_response | N4: 0 | O4: 0 | P4: 0 | Q4: 0 | R4: 1 | S4: 1 | T4: 0 | U4: 1 | W4: 1 | X4: 0 | Y4: 0 | Z4: wrong_rf_optimization | AA4: Response focuses on parallelizing and chunking RF predict loop. No identification of neighbor-feature construction bottleneck, no topology separation, no adjacency structure. | AB4: Experiment_Output/OpenAI/Temp_0.0/output_F01_OpenAI_temp_00_rep_003.md | AC4: Score_Input/S__OpenAI_GPT50moderate__F01__temp_00__rep_003.md | AD4: Score_Output/S__OpenAI_GPT50moderate__F01__temp_00__rep_003.md | AE4: Score_Output_Normalized/S__OpenAI_GPT50moderate__F01__temp_00__rep_003.json | AF4: 2525 | AG4: 309 | AH4: 953
A5: TRACE_20260611 | B5: OpenAI_F01_T00_R004 | C5: OpenAI | D5: GPT 5.0 moderate | E5: 0 | F5: copilot_ui_selected_unverified | G5: =MID(B5,FIND("_T",B5)+2,2)/10 -> 0 | H5: F01 | I5: RF_WRAPPER_ONLY | J5: RF wrapper only | K5: Missing upstream context | L5: 4 | M5: valid_response | N5: 0 | O5: 0 | P5: 0 | Q5: 0 | R5: 1 | S5: 1 | T5: 1 | U5: 1 | W5: 1 | X5: 0 | Y5: 0 | Z5: preallocation_or_parallel_only | AA5: Response focuses on data.table conversion, chunked prediction, and preallocation. No identification of neighbor-feature construction bottleneck, no topology separation, no adjacency structure. | AB5: Experiment_Output/OpenAI/Temp_0.0/output_F01_OpenAI_temp_00_rep_004.md | AC5: Score_Input/S__OpenAI_GPT50moderate__F01__temp_00__rep_004.md | AD5: Score_Output/S__OpenAI_GPT50moderate__F01__temp_00__rep_004.md | AE5: Score_Output_Normalized/S__OpenAI_GPT50moderate__F01__temp_00__rep_004.json | AF5: 2108 | AG5: 277 | AH5: 980 | AI5: mechanism_score_recomputed
A6: TRACE_20260611 | B6: OpenAI_F01_T00_R005 | C6: OpenAI | D6: GPT 5.0 moderate | E6: 0 | F6: copilot_ui_selected_unverified | G6: =MID(B6,FIND("_T",B6)+2,2)/10 -> 0 | H6: F01 | I6: RF_WRAPPER_ONLY | J6: RF wrapper only | K6: Missing upstream context | L6: 5 | M6: valid_response | N6: 0 | O6: 0 | P6: 0 | Q6: 0 | R6: 0 | S6: 1 | T6: 1 | U6: 1 | W6: 0 | X6: 0 | Y6: 0 | Z6: generic_performance_advice | AA6: Response focuses on data.table conversion, chunked predict, and parallelization of RF prediction loop. No identification of neighbor topology or feature construction bottleneck. | AB6: Experiment_Output/OpenAI/Temp_0.0/output_F01_OpenAI_temp_00_rep_005.md | AC6: Score_Input/S__OpenAI_GPT50moderate__F01__temp_00__rep_005.md | AD6: Score_Output/S__OpenAI_GPT50moderate__F01__temp_00__rep_005.md | AE6: Score_Output_Normalized/S__OpenAI_GPT50moderate__F01__temp_00__rep_005.json | AF6: 2432 | AG6: 306 | AH6: 961
A7: TRACE_20260611 | B7: OpenAI_F01_T00_R006 | C7: OpenAI | D7: GPT 5.0 moderate | E7: 0 | F7: copilot_ui_selected_unverified | G7: =MID(B7,FIND("_T",B7)+2,2)/10 -> 0 | H7: F01 | I7: RF_WRAPPER_ONLY | J7: RF wrapper only | K7: Missing upstream context | L7: 6 | M7: valid_response | N7: 0 | O7: 0 | P7: 0 | Q7: 0 | R7: 0 | S7: 1 | T7: 0 | U7: 1 | W7: 0 | X7: 0 | Y7: 0 | Z7: wrong_rf_optimization | AA7: Response focuses on chunked/parallel RF prediction and data.table filtering. No identification of neighbor topology bottleneck or adjacency separation. Treats RF predict as main bottleneck. | AB7: Experiment_Output/OpenAI/Temp_0.0/output_F01_OpenAI_temp_00_rep_006.md | AC7: Score_Input/S__OpenAI_GPT50moderate__F01__temp_00__rep_006.md | AD7: Score_Output/S__OpenAI_GPT50moderate__F01__temp_00__rep_006.md | AE7: Score_Output_Normalized/S__OpenAI_GPT50moderate__F01__temp_00__rep_006.json | AF7: 2314 | AG7: 291 | AH7: 968
A8: TRACE_20260611 | B8: OpenAI_F01_T00_R007 | C8: OpenAI | D8: GPT 5.0 moderate | E8: 0 | F8: copilot_ui_selected_unverified | G8: =MID(B8,FIND("_T",B8)+2,2)/10 -> 0 | H8: F01 | I8: RF_WRAPPER_ONLY | J8: RF wrapper only | K8: Missing upstream context | L8: 7 | M8: valid_response | N8: 0 | O8: 0 | P8: 0 | Q8: 0 | R8: 1 | S8: 1 | T8: 1 | U8: 1 | W8: 1 | X8: 0 | Y8: 0 | Z8: generic_performance_advice | AA8: Response focuses on data.table conversion, chunked prediction, and parallelization. No identification of neighbor topology bottleneck or adjacency separation. Generic performance advice only. | AB8: Experiment_Output/OpenAI/Temp_0.0/output_F01_OpenAI_temp_00_rep_007.md | AC8: Score_Input/S__OpenAI_GPT50moderate__F01__temp_00__rep_007.md | AD8: Score_Output/S__OpenAI_GPT50moderate__F01__temp_00__rep_007.md | AE8: Score_Output_Normalized/S__OpenAI_GPT50moderate__F01__temp_00__rep_007.json | AF8: 2543 | AG8: 322 | AH8: 975 | AI8: mechanism_score_recomputed
A9: TRACE_20260611 | B9: OpenAI_F01_T00_R008 | C9: OpenAI | D9: GPT 5.0 moderate | E9: 0 | F9: copilot_ui_selected_unverified | G9: =MID(B9,FIND("_T",B9)+2,2)/10 -> 0 | H9: F01 | I9: RF_WRAPPER_ONLY | J9: RF wrapper only | K9: Missing upstream context | L9: 8 | M9: valid_response | N9: 0 | O9: 0 | P9: 0 | Q9: 0 | R9: 1 | S9: 1 | T9: 1 | U9: 1 | W9: 1 | X9: 0 | Y9: 0 | Z9: generic_performance_advice | AA9: Response focuses on prediction loop parallelization, chunking, and data.table conversion. No identification of neighbor topology bottleneck or adjacency separation. Generic performance advice. | AB9: Experiment_Output/OpenAI/Temp_0.0/output_F01_OpenAI_temp_00_rep_008.md | AC9: Score_Input/S__OpenAI_GPT50moderate__F01__temp_00__rep_008.md | AD9: Score_Output/S__OpenAI_GPT50moderate__F01__temp_00__rep_008.md | AE9: Score_Output_Normalized/S__OpenAI_GPT50moderate__F01__temp_00__rep_008.json | AF9: 2742 | AG9: 348 | AH9: 976 | AI9: mechanism_score_recomputed
A10: TRACE_20260611 | B10: OpenAI_F01_T00_R009 | C10: OpenAI | D10: GPT 5.0 moderate | E10: 0 | F10: copilot_ui_selected_unverified | G10: =MID(B10,FIND("_T",B10)+2,2)/10 -> 0 | H10: F01 | I10: RF_WRAPPER_ONLY | J10: RF wrapper only | K10: Missing upstream context | L10: 9 | M10: valid_response | N10: 0 | O10: 0 | P10: 0 | Q10: 0 | R10: 1 | S10: 1 | T10: 1 | U10: 1 | W10: 1 | X10: 0 | Y10: 0 | Z10: generic_performance_advice | AA10: Response focuses on chunked prediction and parallelization of RF predict loop. No identification of neighbor-feature construction bottleneck, no topology separation, no adjacency structure. | AB10: Experiment_Output/OpenAI/Temp_0.0/output_F01_OpenAI_temp_00_rep_009.md | AC10: Score_Input/S__OpenAI_GPT50moderate__F01__temp_00__rep_009.md | AD10: Score_Output/S__OpenAI_GPT50moderate__F01__temp_00__rep_009.md | AE10: Score_Output_Normalized/S__OpenAI_GPT50moderate__F01__temp_00__rep_009.json | AF10: 2225 | AG10: 278 | AH10: 973 | AI10: mechanism_score_recomputed
A11: TRACE_20260611 | B11: OpenAI_F01_T00_R010 | C11: OpenAI | D11: GPT 5.0 moderate | E11: 0 | F11: copilot_ui_selected_unverified | G11: =MID(B11,FIND("_T",B11)+2,2)/10 -> 0 | H11: F01 | I11: RF_WRAPPER_ONLY | J11: RF wrapper only | K11: Missing upstream context | L11: 10 | M11: valid_response | N11: 0 | O11: 0 | P11: 0 | Q11: 0 | R11: 0 | S11: 1 | T11: 1 | U11: 1 | W11: 0 | X11: 0 | Y11: 0 | Z11: generic_performance_advice | AA11: Response focuses on data.table conversion and chunked prediction loop optimization. No identification of neighbor topology bottleneck or adjacency separation. Entirely generic performance advice. | AB11: Experiment_Output/OpenAI/Temp_0.0/output_F01_OpenAI_temp_00_rep_010.md | AC11: Score_Input/S__OpenAI_GPT50moderate__F01__temp_00__rep_010.md | AD11: Score_Output/S__OpenAI_GPT50moderate__F01__temp_00__rep_010.md | AE11: Score_Output_Normalized/S__OpenAI_GPT50moderate__F01__temp_00__rep_010.json | AF11: 2243 | AG11: 304 | AH11: 980
A12: TRACE_20260611 | B12: OpenAI_F01_T00_R011 | C12: OpenAI | D12: GPT 5.0 moderate | E12: 0 | F12: copilot_ui_selected_unverified | G12: =MID(B12,FIND("_T",B12)+2,2)/10 -> 0 | H12: F01 | I12: RF_WRAPPER_ONLY | J12: RF wrapper only | K12: Missing upstream context | L12: 11 | M12: valid_response | N12: 0 | O12: 0 | P12: 0 | Q12: 0 | R12: 1 | S12: 1 | T12: 1 | U12: 1 | W12: 1 | X12: 0 | Y12: 0 | Z12: generic_performance_advice | AA12: Response focuses on chunked prediction and parallelization of the RF predict loop. No identification of neighbor-feature construction bottleneck or topology separation. | AB12: Experiment_Output/OpenAI/Temp_0.0/output_F01_OpenAI_temp_00_rep_011.md | AC12: Score_Input/S__OpenAI_GPT50moderate__F01__temp_00__rep_011.md | AD12: Score_Output/S__OpenAI_GPT50moderate__F01__temp_00__rep_011.md | AE12: Score_Output_Normalized/S__OpenAI_GPT50moderate__F01__temp_00__rep_011.json | AF12: 2090 | AG12: 277 | AH12: 953 | AI12: mechanism_score_recomputed
A13: TRACE_20260611 | B13: OpenAI_F01_T00_R012 | C13: OpenAI | D13: GPT 5.0 moderate | E13: 0 | F13: copilot_ui_selected_unverified | G13: =MID(B13,FIND("_T",B13)+2,2)/10 -> 0 | H13: F01 | I13: RF_WRAPPER_ONLY | J13: RF wrapper only | K13: Missing upstream context | L13: 12 | M13: valid_response | N13: 0 | O13: 0 | P13: 0 | Q13: 0 | R13: 0 | S13: 1 | T13: 1 | U13: 1 | W13: 0 | X13: 0 | Y13: 0 | Z13: generic_performance_advice | AA13: Response focuses on data.table conversion, chunked predict, and in-place assignment. No recognition of neighbor topology, adjacency separation, or upstream feature construction bottleneck. | AB13: Experiment_Output/OpenAI/Temp_0.0/output_F01_OpenAI_temp_00_rep_012.md | AC13: Score_Input/S__OpenAI_GPT50moderate__F01__temp_00__rep_012.md | AD13: Score_Output/S__OpenAI_GPT50moderate__F01__temp_00__rep_012.md | AE13: Score_Output_Normalized/S__OpenAI_GPT50moderate__F01__temp_00__rep_012.json | AF13: 2549 | AG13: 323 | AH13: 973
A14: TRACE_20260611 | B14: OpenAI_F01_T00_R013 | C14: OpenAI | D14: GPT 5.0 moderate | E14: 0 | F14: copilot_ui_selected_unverified | G14: =MID(B14,FIND("_T",B14)+2,2)/10 -> 0 | H14: F01 | I14: RF_WRAPPER_ONLY | J14: RF wrapper only | K14: Missing upstream context | L14: 13 | M14: valid_response | N14: 0 | O14: 0 | P14: 0 | Q14: 0 | R14: 0 | S14: 1 | T14: 1 | U14: 1 | W14: 0 | X14: 0 | Y14: 0 | Z14: generic_performance_advice | AA14: Response focuses on chunking predictions and data.table conversion. No identification of neighbor-feature construction bottleneck, no topology separation, no adjacency structure. | AB14: Experiment_Output/OpenAI/Temp_0.0/output_F01_OpenAI_temp_00_rep_013.md | AC14: Score_Input/S__OpenAI_GPT50moderate__F01__temp_00__rep_013.md | AD14: Score_Output/S__OpenAI_GPT50moderate__F01__temp_00__rep_013.md | AE14: Score_Output_Normalized/S__OpenAI_GPT50moderate__F01__temp_00__rep_013.json | AF14: 2154 | AG14: 295 | AH14: 963
A15: TRACE_20260611 | B15: OpenAI_F01_T00_R014 | C15: OpenAI | D15: GPT 5.0 moderate | E15: 0 | F15: copilot_ui_selected_unverified | G15: =MID(B15,FIND("_T",B15)+2,2)/10 -> 0 | H15: F01 | I15: RF_WRAPPER_ONLY | J15: RF wrapper only | K15: Missing upstream context | L15: 14 | M15: valid_response | N15: 0 | O15: 0 | P15: 0 | Q15: 0 | R15: 1 | S15: 1 | T15: 1 | U15: 1 | W15: 1 | X15: 0 | Y15: 0 | Z15: generic_performance_advice | AA15: Response addresses only the visible prediction loop with data.table and chunking. No recognition of upstream neighbor-feature construction bottleneck or topology separation. | AB15: Experiment_Output/OpenAI/Temp_0.0/output_F01_OpenAI_temp_00_rep_014.md | AC15: Score_Input/S__OpenAI_GPT50moderate__F01__temp_00__rep_014.md | AD15: Score_Output/S__OpenAI_GPT50moderate__F01__temp_00__rep_014.md | AE15: Score_Output_Normalized/S__OpenAI_GPT50moderate__F01__temp_00__rep_014.json | AF15: 2329 | AG15: 311 | AH15: 958 | AI15: mechanism_score_recomputed
A16: TRACE_20260611 | B16: OpenAI_F01_T00_R015 | C16: OpenAI | D16: GPT 5.0 moderate | E16: 0 | F16: copilot_ui_selected_unverified | G16: =MID(B16,FIND("_T",B16)+2,2)/10 -> 0 | H16: F01 | I16: RF_WRAPPER_ONLY | J16: RF wrapper only | K16: Missing upstream context | L16: 15 | M16: valid_response | N16: 0 | O16: 0 | P16: 0 | Q16: 0 | R16: 1 | S16: 1 | T16: 1 | U16: 1 | W16: 1 | X16: 0 | Y16: 0 | Z16: generic_performance_advice | AA16: Response focuses on data.table conversion and chunked prediction of the visible loop. No recognition of upstream neighbor-feature construction bottleneck or topology separation. | AB16: Experiment_Output/OpenAI/Temp_0.0/output_F01_OpenAI_temp_00_rep_015.md | AC16: Score_Input/S__OpenAI_GPT50moderate__F01__temp_00__rep_015.md | AD16: Score_Output/S__OpenAI_GPT50moderate__F01__temp_00__rep_015.md | AE16: Score_Output_Normalized/S__OpenAI_GPT50moderate__F01__temp_00__rep_015.json | AF16: 2297 | AG16: 319 | AH16: 962 | AI16: mechanism_score_recomputed
A17: TRACE_20260611 | B17: OpenAI_F01_T00_R016 | C17: OpenAI | D17: GPT 5.0 moderate | E17: 0 | F17: copilot_ui_selected_unverified | G17: =MID(B17,FIND("_T",B17)+2,2)/10 -> 0 | H17: F01 | I17: RF_WRAPPER_ONLY | J17: RF wrapper only | K17: Missing upstream context | L17: 16 | M17: valid_response | N17: 0 | O17: 0 | P17: 0 | Q17: 0 | R17: 1 | S17: 1 | T17: 1 | U17: 1 | W17: 1 | X17: 0 | Y17: 0 | Z17: generic_performance_advice | AA17: Response focuses on data.table conversion and chunked prediction. No identification of neighbor topology bottleneck, no adjacency structure, no separation of static topology from dynamic attributes. | AB17: Experiment_Output/OpenAI/Temp_0.0/output_F01_OpenAI_temp_00_rep_016.md | AC17: Score_Input/S__OpenAI_GPT50moderate__F01__temp_00__rep_016.md | AD17: Score_Output/S__OpenAI_GPT50moderate__F01__temp_00__rep_016.md | AE17: Score_Output_Normalized/S__OpenAI_GPT50moderate__F01__temp_00__rep_016.json | AF17: 2482 | AG17: 335 | AH17: 983 | AI17: mechanism_score_recomputed
A18: TRACE_20260611 | B18: OpenAI_F01_T00_R017 | C18: OpenAI | D18: GPT 5.0 moderate | E18: 0 | F18: copilot_ui_selected_unverified | G18: =MID(B18,FIND("_T",B18)+2,2)/10 -> 0 | H18: F01 | I18: RF_WRAPPER_ONLY | J18: RF wrapper only | K18: Missing upstream context | L18: 17 | M18: valid_response | N18: 0 | O18: 0 | P18: 0 | Q18: 0 | R18: 1 | S18: 1 | T18: 1 | U18: 1 | W18: 1 | X18: 0 | Y18: 0 | Z18: generic_performance_advice | AA18: Response focuses on chunking, parallelizing, and data.table conversion for predict loop. No identification of neighbor topology bottleneck or adjacency separation. | AB18: Experiment_Output/OpenAI/Temp_0.0/output_F01_OpenAI_temp_00_rep_017.md | AC18: Score_Input/S__OpenAI_GPT50moderate__F01__temp_00__rep_017.md | AD18: Score_Output/S__OpenAI_GPT50moderate__F01__temp_00__rep_017.md | AE18: Score_Output_Normalized/S__OpenAI_GPT50moderate__F01__temp_00__rep_017.json | AF18: 2394 | AG18: 304 | AH18: 948 | AI18: mechanism_score_recomputed
A19: TRACE_20260611 | B19: OpenAI_F01_T00_R018 | C19: OpenAI | D19: GPT 5.0 moderate | E19: 0 | F19: copilot_ui_selected_unverified | G19: =MID(B19,FIND("_T",B19)+2,2)/10 -> 0 | H19: F01 | I19: RF_WRAPPER_ONLY | J19: RF wrapper only | K19: Missing upstream context | L19: 18 | M19: valid_response | N19: 0 | O19: 0 | P19: 0 | Q19: 0 | R19: 0 | S19: 1 | T19: 1 | U19: 1 | W19: 0 | X19: 0 | Y19: 0 | Z19: generic_performance_advice | AA19: Response focuses on chunked prediction, data.table filtering, and parallelization of the RF predict loop. No identification of neighbor topology or feature construction bottleneck. | AB19: Experiment_Output/OpenAI/Temp_0.0/output_F01_OpenAI_temp_00_rep_018.md | AC19: Score_Input/S__OpenAI_GPT50moderate__F01__temp_00__rep_018.md | AD19: Score_Output/S__OpenAI_GPT50moderate__F01__temp_00__rep_018.md | AE19: Score_Output_Normalized/S__OpenAI_GPT50moderate__F01__temp_00__rep_018.json | AF19: 2576 | AG19: 329 | AH19: 965
A20: TRACE_20260611 | B20: OpenAI_F01_T00_R019 | C20: OpenAI | D20: GPT 5.0 moderate | E20: 0 | F20: copilot_ui_selected_unverified | G20: =MID(B20,FIND("_T",B20)+2,2)/10 -> 0 | H20: F01 | I20: RF_WRAPPER_ONLY | J20: RF wrapper only | K20: Missing upstream context | L20: 19 | M20: valid_response | N20: 0 | O20: 0 | P20: 0 | Q20: 0 | R20: 0 | S20: 1 | T20: 1 | U20: 1 | W20: 0 | X20: 0 | Y20: 0 | Z20: generic_performance_advice | AA20: Response focuses on data.table conversion and chunked predict calls. No identification of neighbor-feature construction bottleneck, no topology separation, no adjacency structure. | AB20: Experiment_Output/OpenAI/Temp_0.0/output_F01_OpenAI_temp_00_rep_019.md | AC20: Score_Input/S__OpenAI_GPT50moderate__F01__temp_00__rep_019.md | AD20: Score_Output/S__OpenAI_GPT50moderate__F01__temp_00__rep_019.md | AE20: Score_Output_Normalized/S__OpenAI_GPT50moderate__F01__temp_00__rep_019.json | AF20: 2308 | AG20: 302 | AH20: 964
A21: TRACE_20260611 | B21: OpenAI_F01_T00_R020 | C21: OpenAI | D21: GPT 5.0 moderate | E21: 0 | F21: copilot_ui_selected_unverified | G21: =MID(B21,FIND("_T",B21)+2,2)/10 -> 0 | H21: F01 | I21: RF_WRAPPER_ONLY | J21: RF wrapper only | K21: Missing upstream context | L21: 20 | M21: valid_response | N21: 0 | O21: 0 | P21: 0 | Q21: 0 | R21: 0 | S21: 1 | T21: 1 | U21: 1 | W21: 0 | X21: 0 | Y21: 0 | Z21: generic_performance_advice | AA21: Response focuses on chunking and parallelizing RF predict calls. No identification of neighbor-feature construction bottleneck, no topology separation, no adjacency structure. | AB21: Experiment_Output/OpenAI/Temp_0.0/output_F01_OpenAI_temp_00_rep_020.md | AC21: Score_Input/S__OpenAI_GPT50moderate__F01__temp_00__rep_020.md | AD21: Score_Output/S__OpenAI_GPT50moderate__F01__temp_00__rep_020.md | AE21: Score_Output_Normalized/S__OpenAI_GPT50moderate__F01__temp_00__rep_020.json | AF21: 2143 | AG21: 285 | AH21: 960
A22: TRACE_20260611 | B22: OpenAI_F01_T00_R021 | C22: OpenAI | D22: GPT 5.0 moderate | E22: 0 | F22: copilot_ui_selected_unverified | G22: =MID(B22,FIND("_T",B22)+2,2)/10 -> 0 | H22: F01 | I22: RF_WRAPPER_ONLY | J22: RF wrapper only | K22: Missing upstream context | L22: 21 | M22: valid_response | N22: 0 | O22: 0 | P22: 0 | Q22: 0 | R22: 0 | S22: 1 | T22: 1 | U22: 1 | W22: 0 | X22: 0 | Y22: 0 | Z22: wrong_rf_optimization | AA22: Response focuses on chunked predict() and data.table conversion for the RF prediction loop. No identification of neighbor-feature construction bottleneck or topology separation. | AB22: Experiment_Output/OpenAI/Temp_0.0/output_F01_OpenAI_temp_00_rep_021.md | AC22: Score_Input/S__OpenAI_GPT50moderate__F01__temp_00__rep_021.md | AD22: Score_Output/S__OpenAI_GPT50moderate__F01__temp_00__rep_021.md | AE22: Score_Output_Normalized/S__OpenAI_GPT50moderate__F01__temp_00__rep_021.json | AF22: 1928 | AG22: 254 | AH22: 945
A23: TRACE_20260611 | B23: OpenAI_F01_T00_R022 | C23: OpenAI | D23: GPT 5.0 moderate | E23: 0 | F23: copilot_ui_selected_unverified | G23: =MID(B23,FIND("_T",B23)+2,2)/10 -> 0 | H23: F01 | I23: RF_WRAPPER_ONLY | J23: RF wrapper only | K23: Missing upstream context | L23: 22 | M23: valid_response | N23: 0 | O23: 0 | P23: 0 | Q23: 0 | R23: 1 | S23: 1 | T23: 1 | U23: 1 | W23: 1 | X23: 0 | Y23: 0 | Z23: generic_performance_advice | AA23: Response focuses on data.table filtering and chunked predict loop. No identification of neighbor topology bottleneck, no adjacency separation, no upstream feature construction insight. | AB23: Experiment_Output/OpenAI/Temp_0.0/output_F01_OpenAI_temp_00_rep_022.md | AC23: Score_Input/S__OpenAI_GPT50moderate__F01__temp_00__rep_022.md | AD23: Score_Output/S__OpenAI_GPT50moderate__F01__temp_00__rep_022.md | AE23: Score_Output_Normalized/S__OpenAI_GPT50moderate__F01__temp_00__rep_022.json | AF23: 2074 | AG23: 285 | AH23: 969 | AI23: mechanism_score_recomputed
A24: TRACE_20260611 | B24: OpenAI_F01_T00_R023 | C24: OpenAI | D24: GPT 5.0 moderate | E24: 0 | F24: copilot_ui_selected_unverified | G24: =MID(B24,FIND("_T",B24)+2,2)/10 -> 0 | H24: F01 | I24: RF_WRAPPER_ONLY | J24: RF wrapper only | K24: Missing upstream context | L24: 23 | M24: valid_response | N24: 0 | O24: 0 | P24: 0 | Q24: 0 | R24: 1 | S24: 1 | T24: 1 | U24: 1 | W24: 1 | X24: 0 | Y24: 0 | Z24: generic_performance_advice | AA24: Response focuses on parallelizing and chunking RF prediction with data.table. No identification of neighbor topology bottleneck or adjacency separation. Generic performance advice only. | AB24: Experiment_Output/OpenAI/Temp_0.0/output_F01_OpenAI_temp_00_rep_023.md | AC24: Score_Input/S__OpenAI_GPT50moderate__F01__temp_00__rep_023.md | AD24: Score_Output/S__OpenAI_GPT50moderate__F01__temp_00__rep_023.md | AE24: Score_Output_Normalized/S__OpenAI_GPT50moderate__F01__temp_00__rep_023.json | AF24: 2385 | AG24: 297 | AH24: 970 | AI24: mechanism_score_recomputed
A25: TRACE_20260611 | B25: OpenAI_F01_T00_R024 | C25: OpenAI | D25: GPT 5.0 moderate | E25: 0 | F25: copilot_ui_selected_unverified | G25: =MID(B25,FIND("_T",B25)+2,2)/10 -> 0 | H25: F01 | I25: RF_WRAPPER_ONLY | J25: RF wrapper only | K25: Missing upstream context | L25: 24 | M25: valid_response | N25: 0 | O25: 0 | P25: 0 | Q25: 0 | R25: 0 | S25: 1 | T25: 0 | U25: 1 | W25: 0 | X25: 0 | Y25: 0 | Z25: wrong_rf_optimization | AA25: Response focuses on dplyr-to-data.table conversion and RF prediction loop optimization. No identification of neighbor topology bottleneck or adjacency separation. | AB25: Experiment_Output/OpenAI/Temp_0.0/output_F01_OpenAI_temp_00_rep_024.md | AC25: Score_Input/S__OpenAI_GPT50moderate__F01__temp_00__rep_024.md | AD25: Score_Output/S__OpenAI_GPT50moderate__F01__temp_00__rep_024.md | AE25: Score_Output_Normalized/S__OpenAI_GPT50moderate__F01__temp_00__rep_024.json | AF25: 2234 | AG25: 303 | AH25: 942
A26: TRACE_20260611 | B26: OpenAI_F01_T00_R025 | C26: OpenAI | D26: GPT 5.0 moderate | E26: 0 | F26: copilot_ui_selected_unverified | G26: =MID(B26,FIND("_T",B26)+2,2)/10 -> 0 | H26: F01 | I26: RF_WRAPPER_ONLY | J26: RF wrapper only | K26: Missing upstream context | L26: 25 | M26: valid_response | N26: 0 | O26: 0 | P26: 0 | Q26: 0 | R26: 0 | S26: 1 | T26: 1 | U26: 1 | W26: 0 | X26: 0 | Y26: 0 | Z26: generic_performance_advice | AA26: Response focuses on chunked prediction and data.table filtering. No identification of neighbor topology bottleneck, no adjacency structure, no feature construction optimization. | AB26: Experiment_Output/OpenAI/Temp_0.0/output_F01_OpenAI_temp_00_rep_025.md | AC26: Score_Input/S__OpenAI_GPT50moderate__F01__temp_00__rep_025.md | AD26: Score_Output/S__OpenAI_GPT50moderate__F01__temp_00__rep_025.md | AE26: Score_Output_Normalized/S__OpenAI_GPT50moderate__F01__temp_00__rep_025.json | AF26: 2275 | AG26: 299 | AH26: 962
A27: TRACE_20260611 | B27: OpenAI_F01_T00_R026 | C27: OpenAI | D27: GPT 5.0 moderate | E27: 0 | F27: copilot_ui_selected_unverified | G27: =MID(B27,FIND("_T",B27)+2,2)/10 -> 0 | H27: F01 | I27: RF_WRAPPER_ONLY | J27: RF wrapper only | K27: Missing upstream context | L27: 26 | M27: valid_response | N27: 0 | O27: 0 | P27: 0 | Q27: 0 | R27: 1 | S27: 1 | T27: 1 | U27: 1 | W27: 1 | X27: 0 | Y27: 0 | Z27: generic_performance_advice | AA27: Response focuses on chunking, parallelization, and data.table for predict loop. No identification of neighbor-feature construction bottleneck or topology separation. | AB27: Experiment_Output/OpenAI/Temp_0.0/output_F01_OpenAI_temp_00_rep_026.md | AC27: Score_Input/S__OpenAI_GPT50moderate__F01__temp_00__rep_026.md | AD27: Score_Output/S__OpenAI_GPT50moderate__F01__temp_00__rep_026.md | AE27: Score_Output_Normalized/S__OpenAI_GPT50moderate__F01__temp_00__rep_026.json | AF27: 2334 | AG27: 296 | AH27: 950 | AI27: mechanism_score_recomputed
A28: TRACE_20260611 | B28: OpenAI_F01_T00_R027 | C28: OpenAI | D28: GPT 5.0 moderate | E28: 0 | F28: copilot_ui_selected_unverified | G28: =MID(B28,FIND("_T",B28)+2,2)/10 -> 0 | H28: F01 | I28: RF_WRAPPER_ONLY | J28: RF wrapper only | K28: Missing upstream context | L28: 27 | M28: valid_response | N28: 0 | O28: 0 | P28: 0 | Q28: 0 | R28: 1 | S28: 1 | T28: 1 | U28: 1 | W28: 1 | X28: 0 | Y28: 0 | Z28: generic_performance_advice | AA28: Response focuses on parallelizing and chunking predict() calls with data.table filtering. No identification of neighbor topology bottleneck or adjacency separation. | AB28: Experiment_Output/OpenAI/Temp_0.0/output_F01_OpenAI_temp_00_rep_027.md | AC28: Score_Input/S__OpenAI_GPT50moderate__F01__temp_00__rep_027.md | AD28: Score_Output/S__OpenAI_GPT50moderate__F01__temp_00__rep_027.md | AE28: Score_Output_Normalized/S__OpenAI_GPT50moderate__F01__temp_00__rep_027.json | AF28: 2233 | AG28: 271 | AH28: 949 | AI28: mechanism_score_recomputed
A29: TRACE_20260611 | B29: OpenAI_F01_T00_R028 | C29: OpenAI | D29: GPT 5.0 moderate | E29: 0 | F29: copilot_ui_selected_unverified | G29: =MID(B29,FIND("_T",B29)+2,2)/10 -> 0 | H29: F01 | I29: RF_WRAPPER_ONLY | J29: RF wrapper only | K29: Missing upstream context | L29: 28 | M29: valid_response | N29: 0 | O29: 0 | P29: 0 | Q29: 0 | R29: 0 | S29: 1 | T29: 0 | U29: 1 | W29: 0 | X29: 0 | Y29: 0 | Z29: wrong_rf_optimization | AA29: Response focuses on chunked parallel RF prediction and data.table filtering. No identification of neighbor topology bottleneck or adjacency separation. Misdiagnoses bottleneck entirely. | AB29: Experiment_Output/OpenAI/Temp_0.0/output_F01_OpenAI_temp_00_rep_028.md | AC29: Score_Input/S__OpenAI_GPT50moderate__F01__temp_00__rep_028.md | AD29: Score_Output/S__OpenAI_GPT50moderate__F01__temp_00__rep_028.md | AE29: Score_Output_Normalized/S__OpenAI_GPT50moderate__F01__temp_00__rep_028.json | AF29: 2167 | AG29: 258 | AH29: 965
A30: TRACE_20260611 | B30: OpenAI_F01_T00_R029 | C30: OpenAI | D30: GPT 5.0 moderate | E30: 0 | F30: copilot_ui_selected_unverified | G30: =MID(B30,FIND("_T",B30)+2,2)/10 -> 0 | H30: F01 | I30: RF_WRAPPER_ONLY | J30: RF wrapper only | K30: Missing upstream context | L30: 29 | M30: valid_response | N30: 0 | O30: 0 | P30: 0 | Q30: 0 | R30: 0 | S30: 1 | T30: 0 | U30: 1 | W30: 0 | X30: 0 | Y30: 0 | Z30: wrong_rf_optimization | AA30: Response focuses entirely on parallelizing and chunking RF predict calls. No identification of neighbor-feature construction bottleneck, no topology separation, no adjacency structure. | AB30: Experiment_Output/OpenAI/Temp_0.0/output_F01_OpenAI_temp_00_rep_029.md | AC30: Score_Input/S__OpenAI_GPT50moderate__F01__temp_00__rep_029.md | AD30: Score_Output/S__OpenAI_GPT50moderate__F01__temp_00__rep_029.md | AE30: Score_Output_Normalized/S__OpenAI_GPT50moderate__F01__temp_00__rep_029.json | AF30: 2432 | AG30: 308 | AH30: 964
A31: TRACE_20260611 | B31: OpenAI_F01_T00_R030 | C31: OpenAI | D31: GPT 5.0 moderate | E31: 0 | F31: copilot_ui_selected_unverified | G31: =MID(B31,FIND("_T",B31)+2,2)/10 -> 0 | H31: F01 | I31: RF_WRAPPER_ONLY | J31: RF wrapper only | K31: Missing upstream context | L31: 30 | M31: valid_response | N31: 0 | O31: 0 | P31: 0 | Q31: 0 | R31: 0 | S31: 1 | T31: 1 | U31: 1 | W31: 0 | X31: 0 | Y31: 0 | Z31: generic_performance_advice | AA31: Response focuses on chunking, parallelization, and data.table for predict loop. No identification of neighbor topology bottleneck or adjacency separation. | AB31: Experiment_Output/OpenAI/Temp_0.0/output_F01_OpenAI_temp_00_rep_030.md | AC31: Score_Input/S__OpenAI_GPT50moderate__F01__temp_00__rep_030.md | AD31: Score_Output/S__OpenAI_GPT50moderate__F01__temp_00__rep_030.md | AE31: Score_Output_Normalized/S__OpenAI_GPT50moderate__F01__temp_00__rep_030.json | AF31: 2474 | AG31: 322 | AH31: 939
A32: TRACE_20260611 | B32: OpenAI_F02_T00_R001 | C32: OpenAI | D32: GPT 5.0 moderate | E32: 0 | F32: copilot_ui_selected_unverified | G32: =MID(B32,FIND("_T",B32)+2,2)/10 -> 0 | H32: F02 | I32: CODE_ONLY_NO_HINT | J32: Code only, no hint | K32: Code-visible neutral | L32: 1 | M32: valid_response | N32: 2 | O32: 2 | P32: 2 | Q32: 2 | R32: 2 | S32: 1 | T32: 2 | U32: 2 | W32: 10 | X32: 1 | Y32: 1 | Z32: adjacency_table_success | AA32: Identifies per-cell-year list bottleneck, builds static neighbor pairs once, joins dynamic yearly attributes via data.table, computes all stats vectorized, preserves RF and NA handling. | AB32: Experiment_Output/OpenAI/Temp_0.0/output_F02_OpenAI_temp_00_rep_001.md | AC32: Score_Input/S__OpenAI_GPT50moderate__F02__temp_00__rep_001.md | AD32: Score_Output/S__OpenAI_GPT50moderate__F02__temp_00__rep_001.md | AE32: Score_Output_Normalized/S__OpenAI_GPT50moderate__F02__temp_00__rep_001.json | AF32: 3840 | AG32: 511 | AH32: 968
A33: TRACE_20260611 | B33: OpenAI_F02_T00_R002 | C33: OpenAI | D33: GPT 5.0 moderate | E33: 0 | F33: copilot_ui_selected_unverified | G33: =MID(B33,FIND("_T",B33)+2,2)/10 -> 0 | H33: F02 | I33: CODE_ONLY_NO_HINT | J33: Code only, no hint | K33: Code-visible neutral | L33: 2 | M33: valid_response | N33: 2 | O33: 2 | P33: 2 | Q33: 2 | R33: 1 | S33: 1 | T33: 2 | U33: 2 | W33: 9 | X33: 1 | Y33: 1 | Z33: adjacency_table_success | AA33: Identifies row-wise string-key bottleneck, builds static neighbor edge table, joins dynamic yearly attributes via data.table, preserves RF model. Minor NA-handling ambiguity. | AB33: Experiment_Output/OpenAI/Temp_0.0/output_F02_OpenAI_temp_00_rep_002.md | AC33: Score_Input/S__OpenAI_GPT50moderate__F02__temp_00__rep_002.md | AD33: Score_Output/S__OpenAI_GPT50moderate__F02__temp_00__rep_002.md | AE33: Score_Output_Normalized/S__OpenAI_GPT50moderate__F02__temp_00__rep_002.json | AF33: 3030 | AG33: 403 | AH33: 956
A34: TRACE_20260611 | B34: OpenAI_F02_T00_R003 | C34: OpenAI | D34: GPT 5.0 moderate | E34: 0 | F34: copilot_ui_selected_unverified | G34: =MID(B34,FIND("_T",B34)+2,2)/10 -> 0 | H34: F02 | I34: CODE_ONLY_NO_HINT | J34: Code only, no hint | K34: Code-visible neutral | L34: 3 | M34: valid_response | N34: 2 | O34: 2 | P34: 2 | Q34: 2 | R34: 2 | S34: 1 | T34: 2 | U34: 2 | W34: 10 | X34: 1 | Y34: 1 | Z34: adjacency_table_success | AA34: Identifies row-wise neighbor lookup bottleneck, precomputes static cell-level edge list, joins dynamic yearly attributes via data.table, preserves stats and trained RF. | AB34: Experiment_Output/OpenAI/Temp_0.0/output_F02_OpenAI_temp_00_rep_003.md | AC34: Score_Input/S__OpenAI_GPT50moderate__F02__temp_00__rep_003.md | AD34: Score_Output/S__OpenAI_GPT50moderate__F02__temp_00__rep_003.md | AE34: Score_Output_Normalized/S__OpenAI_GPT50moderate__F02__temp_00__rep_003.json | AF34: 3521 | AG34: 511 | AH34: 951
A35: TRACE_20260611 | B35: OpenAI_F02_T00_R004 | C35: OpenAI | D35: GPT 5.0 moderate | E35: 0 | F35: copilot_ui_selected_unverified | G35: =MID(B35,FIND("_T",B35)+2,2)/10 -> 0 | H35: F02 | I35: CODE_ONLY_NO_HINT | J35: Code only, no hint | K35: Code-visible neutral | L35: 4 | M35: valid_response | N35: 2 | O35: 2 | P35: 2 | Q35: 2 | R35: 2 | S35: 1 | T35: 2 | U35: 2 | W35: 10 | X35: 1 | Y35: 1 | Z35: adjacency_table_success | AA35: Identifies row-wise string-key bottleneck, builds static neighbor long table joined per year, computes grouped stats via data.table, preserves RF and NA handling. | AB35: Experiment_Output/OpenAI/Temp_0.0/output_F02_OpenAI_temp_00_rep_004.md | AC35: Score_Input/S__OpenAI_GPT50moderate__F02__temp_00__rep_004.md | AD35: Score_Output/S__OpenAI_GPT50moderate__F02__temp_00__rep_004.md | AE35: Score_Output_Normalized/S__OpenAI_GPT50moderate__F02__temp_00__rep_004.json | AF35: 3517 | AG35: 443 | AH35: 945
A36: TRACE_20260611 | B36: OpenAI_F02_T00_R005 | C36: OpenAI | D36: GPT 5.0 moderate | E36: 0 | F36: copilot_ui_selected_unverified | G36: =MID(B36,FIND("_T",B36)+2,2)/10 -> 0 | H36: F02 | I36: CODE_ONLY_NO_HINT | J36: Code only, no hint | K36: Code-visible neutral | L36: 5 | M36: valid_response | N36: 2 | O36: 2 | P36: 2 | Q36: 2 | R36: 2 | S36: 1 | T36: 2 | U36: 2 | W36: 10 | X36: 1 | Y36: 1 | Z36: adjacency_table_success | AA36: Identifies static topology vs dynamic attributes, builds edge table once, joins yearly values via data.table, preserves max/min/mean/NA and trained RF. | AB36: Experiment_Output/OpenAI/Temp_0.0/output_F02_OpenAI_temp_00_rep_005.md | AC36: Score_Input/S__OpenAI_GPT50moderate__F02__temp_00__rep_005.md | AD36: Score_Output/S__OpenAI_GPT50moderate__F02__temp_00__rep_005.md | AE36: Score_Output_Normalized/S__OpenAI_GPT50moderate__F02__temp_00__rep_005.json | AF36: 3419 | AG36: 471 | AH36: 934
A37: TRACE_20260611 | B37: OpenAI_F02_T00_R006 | C37: OpenAI | D37: GPT 5.0 moderate | E37: 0 | F37: copilot_ui_selected_unverified | G37: =MID(B37,FIND("_T",B37)+2,2)/10 -> 0 | H37: F02 | I37: CODE_ONLY_NO_HINT | J37: Code only, no hint | K37: Code-visible neutral | L37: 6 | M37: valid_response | N37: 2 | O37: 2 | P37: 2 | Q37: 2 | R37: 1 | S37: 1 | T37: 2 | U37: 2 | W37: 9 | X37: 1 | Y37: 1 | Z37: adjacency_table_success | AA37: Explicitly precomputes static neighbor pairs once, joins dynamic yearly attributes via data.table, computes per-year max/min/mean stats, preserves RF and numerical results. | AB37: Experiment_Output/OpenAI/Temp_0.0/output_F02_OpenAI_temp_00_rep_006.md | AC37: Score_Input/S__OpenAI_GPT50moderate__F02__temp_00__rep_006.md | AD37: Score_Output/S__OpenAI_GPT50moderate__F02__temp_00__rep_006.md | AE37: Score_Output_Normalized/S__OpenAI_GPT50moderate__F02__temp_00__rep_006.json | AF37: 3388 | AG37: 431 | AH37: 954
A38: TRACE_20260611 | B38: OpenAI_F02_T00_R007 | C38: OpenAI | D38: GPT 5.0 moderate | E38: 0 | F38: copilot_ui_selected_unverified | G38: =MID(B38,FIND("_T",B38)+2,2)/10 -> 0 | H38: F02 | I38: CODE_ONLY_NO_HINT | J38: Code only, no hint | K38: Code-visible neutral | L38: 7 | M38: valid_response | N38: 2 | O38: 2 | P38: 2 | Q38: 2 | R38: 1 | S38: 1 | T38: 2 | U38: 2 | W38: 9 | X38: 1 | Y38: 1 | Z38: adjacency_table_success | AA38: Identifies cell-year list bottleneck, builds static neighbor pairs, expands across years, computes stats via data.table joins. Preserves RF. NA handling slightly vague. | AB38: Experiment_Output/OpenAI/Temp_0.0/output_F02_OpenAI_temp_00_rep_007.md | AC38: Score_Input/S__OpenAI_GPT50moderate__F02__temp_00__rep_007.md | AD38: Score_Output/S__OpenAI_GPT50moderate__F02__temp_00__rep_007.md | AE38: Score_Output_Normalized/S__OpenAI_GPT50moderate__F02__temp_00__rep_007.json | AF38: 3488 | AG38: 465 | AH38: 950
A39: TRACE_20260611 | B39: OpenAI_F02_T00_R008 | C39: OpenAI | D39: GPT 5.0 moderate | E39: 0 | F39: copilot_ui_selected_unverified | G39: =MID(B39,FIND("_T",B39)+2,2)/10 -> 0 | H39: F02 | I39: CODE_ONLY_NO_HINT | J39: Code only, no hint | K39: Code-visible neutral | L39: 8 | M39: valid_response | N39: 2 | O39: 2 | P39: 2 | Q39: 2 | R39: 1 | S39: 1 | T39: 2 | U39: 2 | W39: 9 | X39: 1 | Y39: 1 | Z39: adjacency_table_success | AA39: Identifies per-row string lookup bottleneck, builds static neighbor_dt once, expands to panel for yearly joins, computes grouped stats, preserves RF model. | AB39: Experiment_Output/OpenAI/Temp_0.0/output_F02_OpenAI_temp_00_rep_008.md | AC39: Score_Input/S__OpenAI_GPT50moderate__F02__temp_00__rep_008.md | AD39: Score_Output/S__OpenAI_GPT50moderate__F02__temp_00__rep_008.md | AE39: Score_Output_Normalized/S__OpenAI_GPT50moderate__F02__temp_00__rep_008.json | AF39: 3107 | AG39: 381 | AH39: 937
A40: TRACE_20260611 | B40: OpenAI_F02_T00_R009 | C40: OpenAI | D40: GPT 5.0 moderate | E40: 0 | F40: copilot_ui_selected_unverified | G40: =MID(B40,FIND("_T",B40)+2,2)/10 -> 0 | H40: F02 | I40: CODE_ONLY_NO_HINT | J40: Code only, no hint | K40: Code-visible neutral | L40: 9 | M40: valid_response | N40: 2 | O40: 1 | P40: 2 | Q40: 2 | R40: 2 | S40: 1 | T40: 2 | U40: 2 | W40: 9 | X40: 0 | Y40: 0 | Z40: partial_neighbor_optimization | AA40: Builds neighbor long table and uses data.table joins per variable, but Cartesian year expansion conflates static topology with dynamic attributes rather than explicitly separating them. | AB40: Experiment_Output/OpenAI/Temp_0.0/output_F02_OpenAI_temp_00_rep_009.md | AC40: Score_Input/S__OpenAI_GPT50moderate__F02__temp_00__rep_009.md | AD40: Score_Output/S__OpenAI_GPT50moderate__F02__temp_00__rep_009.md | AE40: Score_Output_Normalized/S__OpenAI_GPT50moderate__F02__temp_00__rep_009.json | AF40: 3013 | AG40: 385 | AH40: 973
...

Sheet Table 1
A3: Count of run_id
D4: Total
A5: F01 | B5: RF wrapper only | C5: Missing upstream context | D5: 240
A6: F02 | B6: Code only, no hint | C6: Code-visible neutral | D6: 240
A7: F03 | B7: Code plus RF frame | C7: RF-frame with code | D7: 240
A8: F04 | B8: Neighbor bottleneck hint | C8: Spatial-neighbor cue | D8: 240
A9: F05 | B9: String-key probe | C9: Line-level probe | D9: 240
A10: F06 | B10: Raster/kernel analogy | C10: Raster/kernel bridge | D10: 240
A11: F07 | B11: Raster invalid irregular topology | C11: Raster/kernel bridge | D11: 240
A12: F08 | B12: Topology invariance | C12: Topology cue | D12: 240
A13: F09 | B13: Adjacency-table option | C13: Representation cue | D13: 240
A14: F10 | B14: Sparse graph frame | C14: Graph cue | D14: 240
A15: F11 | B15: False RF diagnosis | C15: Adversarial diagnosis | D15: 240
A16: F12 | B16: False rbind diagnosis | C16: Adversarial diagnosis | D16: 240
A17: Grand Total | D17: 2880

Sheet Table 3
C4: Count of run_id | D4: Count of file_status | E4: Sum of discovery_success | F4: Sum of publication_grade_success | G4: Average of mechanism_score
A5: F01 | B5: RF wrapper only | C5: 240 | D5: 240 | E5: 0 | F5: 0 | G5: 0.3375 | I5: =D5/$C5 -> 1 | J5: =E5/$C5 -> 0 | K5: =F5/$C5 -> 0
A6: F02 | B6: Code only, no hint | C6: 240 | D6: 240 | E6: 206 | F6: 207 | G6: 9.6666667 | I6: =D6/$C6 -> 1 | J6: =E6/$C6 -> 0.85833333 | K6: =F6/$C6 -> 0.8625
A7: F03 | B7: Code plus RF frame | C7: 240 | D7: 240 | E7: 144 | F7: 144 | G7: 8.625 | I7: =D7/$C7 -> 1 | J7: =E7/$C7 -> 0.6 | K7: =F7/$C7 -> 0.6
A8: F04 | B8: Neighbor bottleneck hint | C8: 240 | D8: 240 | E8: 199 | F8: 199 | G8: 9.4875 | I8: =D8/$C8 -> 1 | J8: =E8/$C8 -> 0.82916667 | K8: =F8/$C8 -> 0.82916667
A9: F05 | B9: String-key probe | C9: 240 | D9: 240 | E9: 196 | F9: 196 | G9: 9.4791667 | I9: =D9/$C9 -> 1 | J9: =E9/$C9 -> 0.81666667 | K9: =F9/$C9 -> 0.81666667
A10: F06 | B10: Raster/kernel analogy | C10: 240 | D10: 240 | E10: 169 | F10: 170 | G10: 9.0333333 | I10: =D10/$C10 -> 1 | J10: =E10/$C10 -> 0.70416667 | K10: =F10/$C10 -> 0.70833333
A11: F07 | B11: Raster invalid irregular topology | C11: 240 | D11: 240 | E11: 164 | F11: 165 | G11: 9.05 | I11: =D11/$C11 -> 1 | J11: =E11/$C11 -> 0.68333333 | K11: =F11/$C11 -> 0.6875
A12: F08 | B12: Topology invariance | C12: 240 | D12: 240 | E12: 229 | F12: 229 | G12: 9.9541667 | I12: =D12/$C12 -> 1 | J12: =E12/$C12 -> 0.95416667 | K12: =F12/$C12 -> 0.95416667
A13: F09 | B13: Adjacency-table option | C13: 240 | D13: 240 | E13: 203 | F13: 204 | G13: 9.4125 | I13: =D13/$C13 -> 1 | J13: =E13/$C13 -> 0.84583333 | K13: =F13/$C13 -> 0.85
A14: F10 | B14: Sparse graph frame | C14: 240 | D14: 240 | E14: 238 | F14: 238 | G14: 9.9583333 | I14: =D14/$C14 -> 1 | J14: =E14/$C14 -> 0.99166667 | K14: =F14/$C14 -> 0.99166667
A15: F11 | B15: False RF diagnosis | C15: 240 | D15: 240 | E15: 154 | F15: 154 | G15: 9.075 | I15: =D15/$C15 -> 1 | J15: =E15/$C15 -> 0.64166667 | K15: =F15/$C15 -> 0.64166667
A16: F12 | B16: False rbind diagnosis | C16: 240 | D16: 240 | E16: 112 | F16: 113 | G16: 7.6208333 | I16: =D16/$C16 -> 1 | J16: =E16/$C16 -> 0.46666667 | K16: =F16/$C16 -> 0.47083333
A17: Grand Total | C17: 2880 | D17: 2880 | E17: 2014 | F17: 2019 | G17: 8.475 | I17: =D17/$C17 -> 1 | J17: =E17/$C17 -> 0.69930556 | K17: =F17/$C17 -> 0.70104167

Sheet Table 4
B4: Count of run_id | C4: Count of file_status | D4: Sum of discovery_success | E4: Sum of publication_grade_success | F4: Average of mechanism_score
A5: GPT 5.0 moderate | B5: 1440 | C5: 1440 | D5: 740 | E5: 745 | F5: 7.81875 | H5: =D5/$C5 -> 0.51388889 | I5: =E5/$C5 -> 0.51736111
A6: Opus 4.6 | B6: 1440 | C6: 1440 | D6: 1274 | E6: 1274 | F6: 9.13125 | H6: =D6/$C6 -> 0.88472222 | I6: =E6/$C6 -> 0.88472222
A7: Grand Total | B7: 2880 | C7: 2880 | D7: 2014 | E7: 2019 | F7: 8.475 | H7: =D7/$C7 -> 0.69930556 | I7: =E7/$C7 -> 0.70104167

Sheet Table 5
C4: 0 | E4: 0.3 | G4: 0.7 | I4: 1
C5: Count of run_id | D5: Sum of discovery_success | E5: Count of run_id | F5: Sum of discovery_success | G5: Count of run_id | H5: Sum of discovery_success | I5: Count of run_id | J5: Sum of discovery_success
A6: F01 | B6: RF_WRAPPER_ONLY | C6: 60 | D6: 0 | E6: 60 | F6: 0 | G6: 60 | H6: 0 | I6: 60 | J6: 0
A7: F02 | B7: CODE_ONLY_NO_HINT | C7: 60 | D7: 52 | E7: 60 | F7: 53 | G7: 60 | H7: 51 | I7: 60 | J7: 50
A8: F03 | B8: CODE_PLUS_RF_FRAME | C8: 60 | D8: 38 | E8: 60 | F8: 33 | G8: 60 | H8: 32 | I8: 60 | J8: 41
A9: F04 | B9: NEIGHBOR_BOTTLENECK_HINT | C9: 60 | D9: 54 | E9: 60 | F9: 54 | G9: 60 | H9: 41 | I9: 60 | J9: 50
A10: F05 | B10: STRING_KEY_REDUNDANCY | C10: 60 | D10: 50 | E10: 60 | F10: 49 | G10: 60 | H10: 46 | I10: 60 | J10: 51
A11: F06 | B11: RASTER_KERNEL_ANALOGY | C11: 60 | D11: 44 | E11: 60 | F11: 42 | G11: 60 | H11: 40 | I11: 60 | J11: 43
A12: F07 | B12: RASTER_INVALID_IRREGULAR | C12: 60 | D12: 35 | E12: 60 | F12: 43 | G12: 60 | H12: 44 | I12: 60 | J12: 42
A13: F08 | B13: TOPOLOGY_INVARIANCE | C13: 60 | D13: 57 | E13: 60 | F13: 57 | G13: 60 | H13: 57 | I13: 60 | J13: 58
A14: F09 | B14: ADJACENCY_TABLE_OPTION | C14: 60 | D14: 51 | E14: 60 | F14: 51 | G14: 60 | H14: 51 | I14: 60 | J14: 50
A15: F10 | B15: SPARSE_GRAPH_FRAME | C15: 60 | D15: 59 | E15: 60 | F15: 60 | G15: 60 | H15: 59 | I15: 60 | J15: 60
A16: F11 | B16: FALSE_RF_DIAGNOSIS | C16: 60 | D16: 41 | E16: 60 | F16: 42 | G16: 60 | H16: 36 | I16: 60 | J16: 35
A17: F12 | B17: FALSE_RBIND_DIAGNOSIS | C17: 60 | D17: 27 | E17: 60 | F17: 28 | G17: 60 | H17: 29 | I17: 60 | J17: 28
A18: Grand Total | C18: 720 | D18: 508 | E18: 720 | F18: 512 | G18: 720 | H18: 486 | I18: 720 | J18: 508
A23: F01 | B23: RF_WRAPPER_ONLY | D23: =D6/C6 -> 0 | F23: =F6/E6 -> 0 | H23: =H6/G6 -> 0 | J23: =J6/I6 -> 0
A24: F02 | B24: CODE_ONLY_NO_HINT | D24: =D7/C7 -> 0.86666667 | F24: =F7/E7 -> 0.88333333 | H24: =H7/G7 -> 0.85 | J24: =J7/I7 -> 0.83333333
A25: F03 | B25: CODE_PLUS_RF_FRAME | D25: =D8/C8 -> 0.63333333 | F25: =F8/E8 -> 0.55 | H25: =H8/G8 -> 0.53333333 | J25: =J8/I8 -> 0.68333333
A26: F04 | B26: NEIGHBOR_BOTTLENECK_HINT | D26: =D9/C9 -> 0.9 | F26: =F9/E9 -> 0.9 | H26: =H9/G9 -> 0.68333333 | J26: =J9/I9 -> 0.83333333
A27: F05 | B27: STRING_KEY_REDUNDANCY | D27: =D10/C10 -> 0.83333333 | F27: =F10/E10 -> 0.81666667 | H27: =H10/G10 -> 0.76666667 | J27: =J10/I10 -> 0.85
A28: F06 | B28: RASTER_KERNEL_ANALOGY | D28: =D11/C11 -> 0.73333333 | F28: =F11/E11 -> 0.7 | H28: =H11/G11 -> 0.66666667 | J28: =J11/I11 -> 0.71666667
A29: F07 | B29: RASTER_INVALID_IRREGULAR | D29: =D12/C12 -> 0.58333333 | F29: =F12/E12 -> 0.71666667 | H29: =H12/G12 -> 0.73333333 | J29: =J12/I12 -> 0.7
A30: F08 | B30: TOPOLOGY_INVARIANCE | D30: =D13/C13 -> 0.95 | F30: =F13/E13 -> 0.95 | H30: =H13/G13 -> 0.95 | J30: =J13/I13 -> 0.96666667
A31: F09 | B31: ADJACENCY_TABLE_OPTION | D31: =D14/C14 -> 0.85 | F31: =F14/E14 -> 0.85 | H31: =H14/G14 -> 0.85 | J31: =J14/I14 -> 0.83333333
A32: F10 | B32: SPARSE_GRAPH_FRAME | D32: =D15/C15 -> 0.98333333 | F32: =F15/E15 -> 1 | H32: =H15/G15 -> 0.98333333 | J32: =J15/I15 -> 1
A33: F11 | B33: FALSE_RF_DIAGNOSIS | D33: =D16/C16 -> 0.68333333 | F33: =F16/E16 -> 0.7 | H33: =H16/G16 -> 0.6 | J33: =J16/I16 -> 0.58333333
A34: F12 | B34: FALSE_RBIND_DIAGNOSIS | D34: =D17/C17 -> 0.45 | F34: =F17/E17 -> 0.46666667 | H34: =H17/G17 -> 0.48333333 | J34: =J17/I17 -> 0.46666667

Sheet Figure 1
A3: Count of run_id
B4: Total
A5: adjacency_table_success | B5: 971 | D5: =B5/B$12 -> 0.33715278
A6: full_correct_solution | B6: 883 | D6: =B6/B$12 -> 0.30659722
A7: generic_performance_advice | B7: 203 | D7: =B7/B$12 -> 0.070486111
A8: partial_neighbor_optimization | B8: 497 | D8: =B8/B$12 -> 0.17256944
A9: preallocation_or_parallel_only | B9: 18 | D9: =B9/B$12 -> 0.00625
A10: sparse_graph_success | B10: 274 | D10: =B10/B$12 -> 0.095138889
A11: wrong_rf_optimization | B11: 34 | D11: =B11/B$12 -> 0.011805556
A12: Grand Total | B12: 2880
A18: adjacency_table_success | B18: 971 | D18: =B18/B$12 -> 0.33715278
A19: full_correct_solution | B19: 883 | D19: =B19/B$12 -> 0.30659722
A20: generic_performance_advice | B20: 203 | D20: =B20/B$12 -> 0.070486111
A21: partial_neighbor_optimization | B21: 497 | D21: =B21/B$12 -> 0.17256944
A22: * | B22: 18 | D22: =B22/B$12 -> 0.00625
A23: sparse_graph_success | B23: 274 | D23: =B23/B$12 -> 0.095138889
A24: wrong_rf_optimization | B24: 34 | D24: =B24/B$12 -> 0.011805556
A28: preallocation_or_parallel_only

Sheet Figure 2 Pivot
B4: Average of bottleneck_identification | C4: Average of topology_invariance | D4: Average of solution_architecture | E4: Average of yearly_attribute_application | F4: Average of numerical_equivalence | G4: Average of raster_handling | H4: Average of rf_handling | I4: Average of implementation_quality
A5: F01 | B5: 0.0041666667 | C5: 0 | D5: 0.0083333333 | E5: 0 | F5: 0.325 | G5: 1 | H5: 1.3166667 | I5: 1.0208333
A6: F02 | B6: 2 | C6: 1.8625 | D6: 1.9625 | E6: 1.9708333 | F6: 1.8708333 | G6: 1 | H6: 1.9916667 | I6: 1.9416667
A7: F03 | B7: 1.9666667 | C7: 1.5875 | D7: 1.7083333 | E7: 1.7208333 | F7: 1.6416667 | G7: 1 | H7: 1.3541667 | I7: 1.7541667
A8: F04 | B8: 1.9958333 | C8: 1.8291667 | D8: 1.8916667 | E8: 1.8791667 | F8: 1.8916667 | G8: 1 | H8: 1.9875 | I8: 1.8916667
A9: F05 | B9: 2 | C9: 1.8166667 | D9: 1.8291667 | E9: 1.9041667 | F9: 1.9291667 | G9: 1 | H9: 1.9541667 | I9: 1.9458333
A10: F06 | B10: 1.9541667 | C10: 1.7125 | D10: 1.8458333 | E10: 1.7083333 | F10: 1.8125 | G10: 1.6791667 | H10: 1.9791667 | I10: 1.8875
A11: F07 | B11: 1.9875 | C11: 1.6875 | D11: 1.7833333 | E11: 1.7375 | F11: 1.8541667 | G11: 1.925 | H11: 1.9791667 | I11: 1.8375
A12: F08 | B12: 2 | C12: 2 | D12: 1.9541667 | E12: 2 | F12: 2 | G12: 1 | H12: 1.9958333 | I12: 1.9291667
A13: F09 | B13: 1.9625 | C13: 1.8666667 | D13: 1.8708333 | E13: 1.8291667 | F13: 1.8833333 | G13: 1 | H13: 2 | I13: 1.8625
A14: F10 | B14: 2 | C14: 1.9916667 | D14: 1.9916667 | E14: 1.9916667 | F14: 1.9833333 | G14: 1 | H14: 2 | I14: 1.9625
A15: F11 | B15: 2 | C15: 1.6416667 | D15: 1.8041667 | E15: 1.8833333 | F15: 1.7458333 | G15: 1 | H15: 2 | I15: 1.8833333
A16: F12 | B16: 1.7833333 | C16: 1.3958333 | D16: 1.575 | E16: 1.275 | F16: 1.5916667 | G16: 1 | H16: 1.9625 | I16: 1.7041667
A17: Grand Total | B17: 1.8045139 | C17: 1.6159722 | D17: 1.6854167 | E17: 1.6583333 | F17: 1.7107639 | G17: 1.1336806 | H17: 1.8767361 | I17: 1.8017361

Sheet Figure 2 Graphs
A1: Family | B1: bottleneck_identification | C1: topology_invariance | D1: solution_architecture | E1: yearly_attribute_application | F1: numerical_equivalence | G1: raster_handling | H1: rf_handling | I1: implementation_quality
A2: F01 | B2: ='Figure 2 Pivot'!B5 -> 0.0041666667 | C2: ='Figure 2 Pivot'!C5 -> 0 | D2: ='Figure 2 Pivot'!D5 -> 0.0083333333 | E2: ='Figure 2 Pivot'!E5 -> 0 | F2: ='Figure 2 Pivot'!F5 -> 0.325 | G2: ='Figure 2 Pivot'!G5 -> 1 | H2: ='Figure 2 Pivot'!H5 -> 1.3166667 | I2: ='Figure 2 Pivot'!I5 -> 1.0208333
A3: F02 | B3: ='Figure 2 Pivot'!B6 -> 2 | C3: ='Figure 2 Pivot'!C6 -> 1.8625 | D3: ='Figure 2 Pivot'!D6 -> 1.9625 | E3: ='Figure 2 Pivot'!E6 -> 1.9708333 | F3: ='Figure 2 Pivot'!F6 -> 1.8708333 | G3: ='Figure 2 Pivot'!G6 -> 1 | H3: ='Figure 2 Pivot'!H6 -> 1.9916667 | I3: ='Figure 2 Pivot'!I6 -> 1.9416667
A4: F03 | B4: ='Figure 2 Pivot'!B7 -> 1.9666667 | C4: ='Figure 2 Pivot'!C7 -> 1.5875 | D4: ='Figure 2 Pivot'!D7 -> 1.7083333 | E4: ='Figure 2 Pivot'!E7 -> 1.7208333 | F4: ='Figure 2 Pivot'!F7 -> 1.6416667 | G4: ='Figure 2 Pivot'!G7 -> 1 | H4: ='Figure 2 Pivot'!H7 -> 1.3541667 | I4: ='Figure 2 Pivot'!I7 -> 1.7541667
A5: F04 | B5: ='Figure 2 Pivot'!B8 -> 1.9958333 | C5: ='Figure 2 Pivot'!C8 -> 1.8291667 | D5: ='Figure 2 Pivot'!D8 -> 1.8916667 | E5: ='Figure 2 Pivot'!E8 -> 1.8791667 | F5: ='Figure 2 Pivot'!F8 -> 1.8916667 | G5: ='Figure 2 Pivot'!G8 -> 1 | H5: ='Figure 2 Pivot'!H8 -> 1.9875 | I5: ='Figure 2 Pivot'!I8 -> 1.8916667
A6: F05 | B6: ='Figure 2 Pivot'!B9 -> 2 | C6: ='Figure 2 Pivot'!C9 -> 1.8166667 | D6: ='Figure 2 Pivot'!D9 -> 1.8291667 | E6: ='Figure 2 Pivot'!E9 -> 1.9041667 | F6: ='Figure 2 Pivot'!F9 -> 1.9291667 | G6: ='Figure 2 Pivot'!G9 -> 1 | H6: ='Figure 2 Pivot'!H9 -> 1.9541667 | I6: ='Figure 2 Pivot'!I9 -> 1.9458333
A7: F06 | B7: ='Figure 2 Pivot'!B10 -> 1.9541667 | C7: ='Figure 2 Pivot'!C10 -> 1.7125 | D7: ='Figure 2 Pivot'!D10 -> 1.8458333 | E7: ='Figure 2 Pivot'!E10 -> 1.7083333 | F7: ='Figure 2 Pivot'!F10 -> 1.8125 | G7: ='Figure 2 Pivot'!G10 -> 1.6791667 | H7: ='Figure 2 Pivot'!H10 -> 1.9791667 | I7: ='Figure 2 Pivot'!I10 -> 1.8875
A8: F07 | B8: ='Figure 2 Pivot'!B11 -> 1.9875 | C8: ='Figure 2 Pivot'!C11 -> 1.6875 | D8: ='Figure 2 Pivot'!D11 -> 1.7833333 | E8: ='Figure 2 Pivot'!E11 -> 1.7375 | F8: ='Figure 2 Pivot'!F11 -> 1.8541667 | G8: ='Figure 2 Pivot'!G11 -> 1.925 | H8: ='Figure 2 Pivot'!H11 -> 1.9791667 | I8: ='Figure 2 Pivot'!I11 -> 1.8375
A9: F08 | B9: ='Figure 2 Pivot'!B12 -> 2 | C9: ='Figure 2 Pivot'!C12 -> 2 | D9: ='Figure 2 Pivot'!D12 -> 1.9541667 | E9: ='Figure 2 Pivot'!E12 -> 2 | F9: ='Figure 2 Pivot'!F12 -> 2 | G9: ='Figure 2 Pivot'!G12 -> 1 | H9: ='Figure 2 Pivot'!H12 -> 1.9958333 | I9: ='Figure 2 Pivot'!I12 -> 1.9291667
A10: F09 | B10: ='Figure 2 Pivot'!B13 -> 1.9625 | C10: ='Figure 2 Pivot'!C13 -> 1.8666667 | D10: ='Figure 2 Pivot'!D13 -> 1.8708333 | E10: ='Figure 2 Pivot'!E13 -> 1.8291667 | F10: ='Figure 2 Pivot'!F13 -> 1.8833333 | G10: ='Figure 2 Pivot'!G13 -> 1 | H10: ='Figure 2 Pivot'!H13 -> 2 | I10: ='Figure 2 Pivot'!I13 -> 1.8625
A11: F10 | B11: ='Figure 2 Pivot'!B14 -> 2 | C11: ='Figure 2 Pivot'!C14 -> 1.9916667 | D11: ='Figure 2 Pivot'!D14 -> 1.9916667 | E11: ='Figure 2 Pivot'!E14 -> 1.9916667 | F11: ='Figure 2 Pivot'!F14 -> 1.9833333 | G11: ='Figure 2 Pivot'!G14 -> 1 | H11: ='Figure 2 Pivot'!H14 -> 2 | I11: ='Figure 2 Pivot'!I14 -> 1.9625
A12: F11 | B12: ='Figure 2 Pivot'!B15 -> 2 | C12: ='Figure 2 Pivot'!C15 -> 1.6416667 | D12: ='Figure 2 Pivot'!D15 -> 1.8041667 | E12: ='Figure 2 Pivot'!E15 -> 1.8833333 | F12: ='Figure 2 Pivot'!F15 -> 1.7458333 | G12: ='Figure 2 Pivot'!G15 -> 1 | H12: ='Figure 2 Pivot'!H15 -> 2 | I12: ='Figure 2 Pivot'!I15 -> 1.8833333
A13: F12 | B13: ='Figure 2 Pivot'!B16 -> 1.7833333 | C13: ='Figure 2 Pivot'!C16 -> 1.3958333 | D13: ='Figure 2 Pivot'!D16 -> 1.575 | E13: ='Figure 2 Pivot'!E16 -> 1.275 | F13: ='Figure 2 Pivot'!F16 -> 1.5916667 | G13: ='Figure 2 Pivot'!G16 -> 1 | H13: ='Figure 2 Pivot'!H16 -> 1.9625 | I13: ='Figure 2 Pivot'!I16 -> 1.7041667
